Workbook

Sheet Order Form
A1: JAGHI TRADE A/S — SUPPLIER ORDER FORM
A2: STEP 1: Fill in Order Details below · STEP 2: Fill in Departures · STEP 3: Go to 'Mail Output' sheet, select table, Ctrl+C and paste into email
A4: ORDER DETAILS
A5: Supplier | B5: e.g. Spreafico, Brio, Eden...
A6: Product | B6: e.g. Bio Kiwi 10x500g
A7: Colli per pallet | B7: 88
A8: Private Label? | B8: Yes
A9: Price (EUR/unit) | B9: e.g. EUR 1.68
A10: Reference / Ref no.
A11: Additional notes
A13: Private Label: Netto → ØGO · Salling → Salling Øko · Dagrofa → Gestus · Coop → Änglamark
A14: Pallet types: Chep Smezzato EPS → Netto, Salling, Dagrofa, AxFood · Euro Pedane Intere → Coop, Rema (>10kg) · Original EPAL Smezzato → Prima Frugt · Always overrideable per line
A16: DEPARTURES & ORDER LINES
A18: Departure 1 Date (Partenza): | C18: Delivery date (DK):
A19: Customer | B19: Private Label | C19: Pallets | D19: Colli (auto) | E19: Pallet type | F19: Box type | G19: Remarks
B20: – | C20: 0 | D20: =IF(C20>0,C20*$B$7,"") | E20: Chep Smezzato EPS | F20: EPS
B21: – | C21: 0 | D21: =IF(C21>0,C21*$B$7,"") | E21: Chep Smezzato EPS | F21: EPS
B22: – | C22: 0 | D22: =IF(C22>0,C22*$B$7,"") | E22: Chep Smezzato EPS | F22: EPS
B23: – | C23: 0 | D23: =IF(C23>0,C23*$B$7,"") | E23: Chep Smezzato EPS | F23: EPS
B24: – | C24: 0 | D24: =IF(C24>0,C24*$B$7,"") | E24: Chep Smezzato EPS | F24: EPS
B25: – | C25: 0 | D25: =IF(C25>0,C25*$B$7,"") | E25: Chep Smezzato EPS | F25: EPS
A26: Subtotal | C26: =SUM(C20:C25) | D26: =SUM(D20:D25)
A28: Departure 2 Date (Partenza): | C28: Delivery date (DK):
A29: Customer | B29: Private Label | C29: Pallets | D29: Colli (auto) | E29: Pallet type | F29: Box type | G29: Remarks
B30: – | C30: 0 | D30: =IF(C30>0,C30*$B$7,"") | E30: Chep Smezzato EPS | F30: EPS
B31: – | C31: 0 | D31: =IF(C31>0,C31*$B$7,"") | E31: Chep Smezzato EPS | F31: EPS
B32: – | C32: 0 | D32: =IF(C32>0,C32*$B$7,"") | E32: Chep Smezzato EPS | F32: EPS
B33: – | C33: 0 | D33: =IF(C33>0,C33*$B$7,"") | E33: Chep Smezzato EPS | F33: EPS
B34: – | C34: 0 | D34: =IF(C34>0,C34*$B$7,"") | E34: Chep Smezzato EPS | F34: EPS
B35: – | C35: 0 | D35: =IF(C35>0,C35*$B$7,"") | E35: Chep Smezzato EPS | F35: EPS
A36: Subtotal | C36: =SUM(C30:C35) | D36: =SUM(D30:D35)
A38: Departure 3 Date (Partenza): | C38: Delivery date (DK):
A39: Customer | B39: Private Label | C39: Pallets | D39: Colli (auto) | E39: Pallet type | F39: Box type | G39: Remarks
B40: – | C40: 0 | D40: =IF(C40>0,C40*$B$7,"") | E40: Chep Smezzato EPS | F40: EPS
B41: – | C41: 0 | D41: =IF(C41>0,C41*$B$7,"") | E41: Chep Smezzato EPS | F41: EPS
B42: – | C42: 0 | D42: =IF(C42>0,C42*$B$7,"") | E42: Chep Smezzato EPS | F42: EPS
B43: – | C43: 0 | D43: =IF(C43>0,C43*$B$7,"") | E43: Chep Smezzato EPS | F43: EPS
B44: – | C44: 0 | D44: =IF(C44>0,C44*$B$7,"") | E44: Chep Smezzato EPS | F44: EPS
B45: – | C45: 0 | D45: =IF(C45>0,C45*$B$7,"") | E45: Chep Smezzato EPS | F45: EPS
A46: Subtotal | C46: =SUM(C40:C45) | D46: =SUM(D40:D45)
...

Sheet Mail Output
A1: MAIL OUTPUT — Select rows 4 onwards → Ctrl+C → Paste into email
A2: This table updates automatically when you fill in the Order Form. Copy and paste directly into OWA/Outlook.
A4: ='Order Form'!B6&" · Price: "&'Order Form'!B9&" · "&'Order Form'!B7&" colli/ped. · Private Label: "&'Order Form'!B8
A6: Departure (Partenza) | B6: Delivery | C6: Customer | D6: Pallets | E6: Colli
A7: ='Order Form'!B18 | B7: ='Order Form'!D18 | C7: ='Order Form'!A20 | D7: =IF('Order Form'!C20>0,'Order Form'!C20,"") | E7: =IF('Order Form'!D20>0,'Order Form'!D20,"")
C8: ='Order Form'!A21 | D8: =IF('Order Form'!C21>0,'Order Form'!C21,"") | E8: =IF('Order Form'!D21>0,'Order Form'!D21,"")
C9: ='Order Form'!A22 | D9: =IF('Order Form'!C22>0,'Order Form'!C22,"") | E9: =IF('Order Form'!D22>0,'Order Form'!D22,"")
C10: ='Order Form'!A23 | D10: =IF('Order Form'!C23>0,'Order Form'!C23,"") | E10: =IF('Order Form'!D23>0,'Order Form'!D23,"")
C11: ='Order Form'!A24 | D11: =IF('Order Form'!C24>0,'Order Form'!C24,"") | E11: =IF('Order Form'!D24>0,'Order Form'!D24,"")
C12: ='Order Form'!A25 | D12: =IF('Order Form'!C25>0,'Order Form'!C25,"") | E12: =IF('Order Form'!D25>0,'Order Form'!D25,"")
C13: Subtotal | D13: ='Order Form'!C26 | E13: ='Order Form'!D26
A14: ='Order Form'!B28 | B14: ='Order Form'!D28 | C14: ='Order Form'!A30 | D14: =IF('Order Form'!C30>0,'Order Form'!C30,"") | E14: =IF('Order Form'!D30>0,'Order Form'!D30,"")
C15: ='Order Form'!A31 | D15: =IF('Order Form'!C31>0,'Order Form'!C31,"") | E15: =IF('Order Form'!D31>0,'Order Form'!D31,"")
C16: ='Order Form'!A32 | D16: =IF('Order Form'!C32>0,'Order Form'!C32,"") | E16: =IF('Order Form'!D32>0,'Order Form'!D32,"")
C17: ='Order Form'!A33 | D17: =IF('Order Form'!C33>0,'Order Form'!C33,"") | E17: =IF('Order Form'!D33>0,'Order Form'!D33,"")
C18: ='Order Form'!A34 | D18: =IF('Order Form'!C34>0,'Order Form'!C34,"") | E18: =IF('Order Form'!D34>0,'Order Form'!D34,"")
C19: ='Order Form'!A35 | D19: =IF('Order Form'!C35>0,'Order Form'!C35,"") | E19: =IF('Order Form'!D35>0,'Order Form'!D35,"")
C20: Subtotal | D20: ='Order Form'!C36 | E20: ='Order Form'!D36
A21: ='Order Form'!B38 | B21: ='Order Form'!D38 | C21: ='Order Form'!A40 | D21: =IF('Order Form'!C40>0,'Order Form'!C40,"") | E21: =IF('Order Form'!D40>0,'Order Form'!D40,"")
C22: ='Order Form'!A41 | D22: =IF('Order Form'!C41>0,'Order Form'!C41,"") | E22: =IF('Order Form'!D41>0,'Order Form'!D41,"")
C23: ='Order Form'!A42 | D23: =IF('Order Form'!C42>0,'Order Form'!C42,"") | E23: =IF('Order Form'!D42>0,'Order Form'!D42,"")
C24: ='Order Form'!A43 | D24: =IF('Order Form'!C43>0,'Order Form'!C43,"") | E24: =IF('Order Form'!D43>0,'Order Form'!D43,"")
C25: ='Order Form'!A44 | D25: =IF('Order Form'!C44>0,'Order Form'!C44,"") | E25: =IF('Order Form'!D44>0,'Order Form'!D44,"")
C26: ='Order Form'!A45 | D26: =IF('Order Form'!C45>0,'Order Form'!C45,"") | E26: =IF('Order Form'!D45>0,'Order Form'!D45,"")
C27: Subtotal | D27: ='Order Form'!C46 | E27: ='Order Form'!D46
C28: TOTAL | D28: ='Order Form'!C48 | E28: ='Order Form'!D48

Sheet Customer Reference
A1: CUSTOMER REFERENCE — Private Label Names & Default Pallet Types
A2: Customer | B2: Private Label | C2: Default pallet type | D2: Notes
A3: Salling Ishøj | B3: Salling Øko | C3: Chep Smezzato EPS
A4: Salling Højbjerg | B4: Salling Øko | C4: Chep Smezzato EPS
A5: Netto Køge | B5: ØGO | C5: Chep Smezzato EPS
A6: Netto Aarslev | B6: ØGO | C6: Chep Smezzato EPS
A7: Coop Hasselager | B7: Änglamark | C7: Euro Pedane Intere | D7: Always PAP boxes
A8: Coop Brøndby | B8: Änglamark | C8: Euro Pedane Intere | D8: Always PAP boxes
A9: Rema 1000 | B9: – | C9: Euro Pedane Intere | D9: Euro Pedane Intere if >10kg; Chep Smezzato EPS if <10kg
A10: Dagrofa Vejle | B10: Gestus | C10: Chep Smezzato EPS
A11: AxFood DAGAB (Sweden) | B11: – | C11: Chep Smezzato EPS | D11: Always PAP boxes
A12: CE Larsen Aarhus | B12: – | C12: Chep Smezzato EPS
A13: Eurofrugt Hinnerup | B13: – | C13: Chep Smezzato EPS
A14: Prima Frugt (Ishøj) | B14: – | C14: Original EPAL Smezzato
A15: Brdr. Kjær | B15: – | C15: Chep Smezzato EPS
A16: Nemlig Brøndby | B16: – | C16: Chep Smezzato EPS
